<?xml version="1.0"?>
<robot xmlns:sensor="http://playerstage.sourceforge.net/gazebo/xmlschema/#sensor"
       xmlns:controller="http://playerstage.sourceforge.net/gazebo/xmlschema/#controller"
       xmlns:interface="http://playerstage.sourceforge.net/gazebo/xmlschema/#interface"
       xmlns:xacro="http://ros.org/wiki/xacro">

  <!-- Xacro properties -->
  <xacro:property name="M_PI" value="3.1415926535897931" />

  <xacro:macro name="nimbus_eef_placeholder" params="parent *origin">
    <joint name="${parent}_nimbus_eef_x_link_joint" type="prismatic">
      <axis xyz="1 0 0" />
      <limit effort="100" velocity="1" lower="-2" upper="2" />
      <xacro:insert_block name="origin" />
      <parent link="${parent}" />
      <child link="nimbus_eef_x_link" />
    </joint>
    <link name="nimbus_eef_x_link" />

    <joint name="nimbus_eef_x_link_nimbus_eef_y_link_joint" type="prismatic">
      <axis xyz="0 1 0" />
      <limit effort="100" velocity="1" lower="-2" upper="2" />
      <parent link="nimbus_eef_x_link" />
      <child link="nimbus_eef_y_link" />
      <origin xyz="0 0 0" rpy="0 0 0" />
    </joint>
    <link name="nimbus_eef_y_link" />

    <joint name="nimbus_eef_y_link_virtual_eef_joint" type="prismatic">
      <axis xyz="0 0 1" />
      <limit effort="100" velocity="1" lower="-2" upper="2" />
      <parent link="nimbus_eef_y_link" />
      <child link="virtual_eef" />
      <origin xyz="0 0 0" rpy="0 0 0" />
    </joint>
    <link name="virtual_eef">
      <visual>
        <geometry>
          <sphere radius="0.01"/>
        </geometry>
        <origin rpy="0 0 0" xyz="0 0 -0.025" />
        <material name="red">
          <color rgba="1 0 0 1" />
        </material>
      </visual>
    </link>

  </xacro:macro>
</robot>
